Workbook
Name Sensordesign: INDEX(#REF!,#REF!)
Name SensorDrawing: INDIRECT("Drawings!B"&Drawings!$B$1)

Sheet Fiber Specification
A2: engionic Femto Gratings GmbH - Am Stollen 19B - 38640 Goslar | H2: V1.14
A4: Production Sheet Number: | E4: Postition: | F4: ='Sensor Specification'!F4 -> 1 | G4: of: | H4: ='Sensor Specification'!H4 -> 1
A5: Offer Number: | C5: ='Sensor Specification'!C5 -> 41260018 | E5: Customer: | F5: ='Sensor Specification'!F5 -> NRL
A6: Customer Product ID: | C6: ='Sensor Specification'!C4 -> 0 | E6: Quantity: | F6: ='Sensor Specification'!F6+'Sensor Specification'!B70 -> 10
A8: Contact: | B8: ='Sensor Specification'!B8 -> 0 | D8: Approved By: | G8: Date:
A10: Remarks: | B10: ='Sensor Specification'!B10 -> Kein Faserwechsel ohne Absprache; Toleranz erstes bis letztes FBG max 5mm
A12: Fiber Specification
A13: Fiber Type | B13: Fiber Core Type | C13: ITU-T | D13: Fiber Cladding Diameter (µm) | E13: Fiber Coating Material | F13: Fiber Manufacturer | H13: Fiber Provided By
A14: SM1330-E9/125PI | B14: =VLOOKUP($A$14,Definitions!C2:I16,2,0) -> Single Mode | C14: =VLOOKUP($A$14,Definitions!C2:I16,7,0) -> - | D14: =VLOOKUP($A$14,Definitions!C2:I16,4,0) -> 125 | E14: =VLOOKUP($A$14,Definitions!C2:I16,5,0) -> Polyimide | F14: =VLOOKUP($A$14,Definitions!C2:I16,6,0) -> J-Fiber | H14: eFG
A16: FBG Specification
B17: Wavelength (nm) | C17: Reflectivity (%) | D17: FWHM (nm) | E17: min SLSR (dB) | F17: FBG Length (mm) | G17: FemtoPlus | H17: Apodized
A18: Nominal Value | B18: - | C18: ='Sensor Specification'!C27 -> 0.1 | D18: ='Sensor Specification'!D27 -> 0.09 | E18: ='Sensor Specification'!E27 -> 8 | F18: ='Sensor Specification'!F27 -> 12 | G18: ='Sensor Specification'!G27 -> 0 | H18: yes
A19: Plus Tolerance | B19: ='Sensor Specification'!B28 -> 0.1 | C19: ='Sensor Specification'!C28 -> 0.04 | D19: ='Sensor Specification'!D28 -> 0.02 | E19: - | F19: ='Sensor Specification'!F28 -> 2
A20: Minus Tolerance | B20: ='Sensor Specification'!B29 -> 0.1 | C20: ='Sensor Specification'!C29 -> 0.04 | D20: ='Sensor Specification'!D29 -> 0.02 | E20: - | F20: ='Sensor Specification'!F29 -> 2
A22: Fiber Design
A25: Additional Specifications
A26: Spectrum Datasheet | B26: Label | C26: Total Fiber Length (mm) | D26: Simplified Packaging1 | E26: Tolerance FBG Spacing (%)2 | F26: FBG Marking | H26: Fiber Input Marking
A27: linear | B27: ='Sensor Specification'!B34 -> on spool | C27: ='Sensor Specification'!C34+'Sensor Specification'!B71+'Sensor Specification'!B72 -> 10150 | D27: no | E27: 1 | F27: black, FBG-length (1mm tolerance) | H27: black
A29: Wavelength Table
A30: FBG Name | B30: Wavelength (nm) | C30: FBG Position (mm) | D30: FBG Lead Out (mm) | E30: FBG Spacing (mm)
A31: =IF(ISBLANK('Sensor Specification'!A38),"",'Sensor Specification'!A38) -> FBG1 | B31: =IF(ISNUMBER('Sensor Specification'!B38),'Sensor Specification'!B38,"") -> 1550.39 | C31: =IF(ISNUMBER('Sensor Specification'!C38),'Sensor Specification'!C38+'Sensor Specification'!$B$71,"") -> 5050 | D31: =IF(ISNUMBER('Sensor Specification'!D38),'Sensor Specification'!D38+'Sensor Specification'!$B$72,"") -> 5100 | E31: -
A32: =IF(ISBLANK('Sensor Specification'!A39),"",'Sensor Specification'!A39) -> FBG2 | B32: =IF(ISNUMBER('Sensor Specification'!B39),'Sensor Specification'!B39,"") -> 1550.39 | C32: =IF(ISNUMBER('Sensor Specification'!C39),'Sensor Specification'!C39+'Sensor Specification'!$B$71,"") -> 5100 | D32: =IF(ISNUMBER('Sensor Specification'!D39),'Sensor Specification'!D39+'Sensor Specification'!$B$72,"") -> 5050 | E32: =IF(ISNUMBER(C32),C32-C31,"") -> 50
A33: =IF(ISBLANK('Sensor Specification'!A40),"",'Sensor Specification'!A40) | B33: =IF(ISNUMBER('Sensor Specification'!B40),'Sensor Specification'!B40,"") | C33: =IF(ISNUMBER('Sensor Specification'!C40),'Sensor Specification'!C40+'Sensor Specification'!$B$71,"") | D33: =IF(ISNUMBER('Sensor Specification'!D40),'Sensor Specification'!D40+'Sensor Specification'!$B$72,"") | E33: =IF(ISNUMBER(C33),C33-C32,"")
A34: =IF(ISBLANK('Sensor Specification'!A41),"",'Sensor Specification'!A41) | B34: =IF(ISNUMBER('Sensor Specification'!B41),'Sensor Specification'!B41,"") | C34: =IF(ISNUMBER('Sensor Specification'!C41),'Sensor Specification'!C41+'Sensor Specification'!$B$71,"") | D34: =IF(ISNUMBER('Sensor Specification'!D41),'Sensor Specification'!D41+'Sensor Specification'!$B$72,"") | E34: =IF(ISNUMBER(C34),C34-C33,"")
A35: =IF(ISBLANK('Sensor Specification'!A42),"",'Sensor Specification'!A42) | B35: =IF(ISNUMBER('Sensor Specification'!B42),'Sensor Specification'!B42,"") | C35: =IF(ISNUMBER('Sensor Specification'!C42),'Sensor Specification'!C42+'Sensor Specification'!$B$71,"") | D35: =IF(ISNUMBER('Sensor Specification'!D42),'Sensor Specification'!D42+'Sensor Specification'!$B$72,"") | E35: =IF(ISNUMBER(C35),C35-C34,"")
A36: =IF(ISBLANK('Sensor Specification'!A43),"",'Sensor Specification'!A43) | B36: =IF(ISNUMBER('Sensor Specification'!B43),'Sensor Specification'!B43,"") | C36: =IF(ISNUMBER('Sensor Specification'!C43),'Sensor Specification'!C43+'Sensor Specification'!$B$71,"") | D36: =IF(ISNUMBER('Sensor Specification'!D43),'Sensor Specification'!D43+'Sensor Specification'!$B$72,"") | E36: =IF(ISNUMBER(C36),C36-C35,"")
A37: =IF(ISBLANK('Sensor Specification'!A44),"",'Sensor Specification'!A44) | B37: =IF(ISNUMBER('Sensor Specification'!B44),'Sensor Specification'!B44,"") | C37: =IF(ISNUMBER('Sensor Specification'!C44),'Sensor Specification'!C44+'Sensor Specification'!$B$71,"") | D37: =IF(ISNUMBER('Sensor Specification'!D44),'Sensor Specification'!D44+'Sensor Specification'!$B$72,"") | E37: =IF(ISNUMBER(C37),C37-C36,"")
A38: =IF(ISBLANK('Sensor Specification'!A45),"",'Sensor Specification'!A45) | B38: =IF(ISNUMBER('Sensor Specification'!B45),'Sensor Specification'!B45,"") | C38: =IF(ISNUMBER('Sensor Specification'!C45),'Sensor Specification'!C45+'Sensor Specification'!$B$71,"") | D38: =IF(ISNUMBER('Sensor Specification'!D45),'Sensor Specification'!D45+'Sensor Specification'!$B$72,"") | E38: =IF(ISNUMBER(C38),C38-C37,"")
A39: =IF(ISBLANK('Sensor Specification'!A46),"",'Sensor Specification'!A46) | B39: =IF(ISNUMBER('Sensor Specification'!B46),'Sensor Specification'!B46,"") | C39: =IF(ISNUMBER('Sensor Specification'!C46),'Sensor Specification'!C46+'Sensor Specification'!$B$71,"") | D39: =IF(ISNUMBER('Sensor Specification'!D46),'Sensor Specification'!D46+'Sensor Specification'!$B$72,"") | E39: =IF(ISNUMBER(C39),C39-C38,"")
A40: =IF(ISBLANK('Sensor Specification'!A47),"",'Sensor Specification'!A47) | B40: =IF(ISNUMBER('Sensor Specification'!B47),'Sensor Specification'!B47,"") | C40: =IF(ISNUMBER('Sensor Specification'!C47),'Sensor Specification'!C47+'Sensor Specification'!$B$71,"") | D40: =IF(ISNUMBER('Sensor Specification'!D47),'Sensor Specification'!D47+'Sensor Specification'!$B$72,"") | E40: =IF(ISNUMBER(C40),C40-C39,"")
A41: =IF(ISBLANK('Sensor Specification'!A48),"",'Sensor Specification'!A48) | B41: =IF(ISNUMBER('Sensor Specification'!B48),'Sensor Specification'!B48,"") | C41: =IF(ISNUMBER('Sensor Specification'!C48),'Sensor Specification'!C48+'Sensor Specification'!$B$71,"") | D41: =IF(ISNUMBER('Sensor Specification'!D48),'Sensor Specification'!D48+'Sensor Specification'!$B$72,"") | E41: =IF(ISNUMBER(C41),C41-C40,"")
A42: =IF(ISBLANK('Sensor Specification'!A49),"",'Sensor Specification'!A49) | B42: =IF(ISNUMBER('Sensor Specification'!B49),'Sensor Specification'!B49,"") | C42: =IF(ISNUMBER('Sensor Specification'!C49),'Sensor Specification'!C49+'Sensor Specification'!$B$71,"") | D42: =IF(ISNUMBER('Sensor Specification'!D49),'Sensor Specification'!D49+'Sensor Specification'!$B$72,"") | E42: =IF(ISNUMBER(C42),C42-C41,"")
A43: =IF(ISBLANK('Sensor Specification'!A50),"",'Sensor Specification'!A50) | B43: =IF(ISNUMBER('Sensor Specification'!B50),'Sensor Specification'!B50,"") | C43: =IF(ISNUMBER('Sensor Specification'!C50),'Sensor Specification'!C50+'Sensor Specification'!$B$71,"") | D43: =IF(ISNUMBER('Sensor Specification'!D50),'Sensor Specification'!D50+'Sensor Specification'!$B$72,"") | E43: =IF(ISNUMBER(C43),C43-C42,"")
... A52: =IF(ISBLANK('Sensor Specification'!A59),"",'Sensor Specification'!A59) | B52: =IF(ISNUMBER('Sensor Specification'!B59),'Sensor Specification'!B59,"") | C52: =IF(ISNUMBER('Sensor Specification'!C59),'Sensor Specification'!C59+'Sensor Specification'!$B$71,"") | D52: =IF(ISNUMBER('Sensor Specification'!D59),'Sensor Specification'!D59+'Sensor Specification'!$B$72,"") | E52: =IF(ISNUMBER(C52),C52-C51,"")
A53: =IF(ISBLANK('Sensor Specification'!A60),"",'Sensor Specification'!A60) | B53: =IF(ISNUMBER('Sensor Specification'!B60),'Sensor Specification'!B60,"") | C53: =IF(ISNUMBER('Sensor Specification'!C60),'Sensor Specification'!C60+'Sensor Specification'!$B$71,"") | D53: =IF(ISNUMBER('Sensor Specification'!D60),'Sensor Specification'!D60+'Sensor Specification'!$B$72,"") | E53: =IF(ISNUMBER(C53),C53-C52,"") | G53: 1) continous fiber with multible FBGs/arrays, to be cut by customer
A54: =IF(ISBLANK('Sensor Specification'!A61),"",'Sensor Specification'!A61) | B54: =IF(ISNUMBER('Sensor Specification'!B61),'Sensor Specification'!B61,"") | C54: =IF(ISNUMBER('Sensor Specification'!C61),'Sensor Specification'!C61+'Sensor Specification'!$B$71,"") | D54: =IF(ISNUMBER('Sensor Specification'!D61),'Sensor Specification'!D61+'Sensor Specification'!$B$72,"") | E54: =IF(ISNUMBER(C54),C54-C53,"")
A55: =IF(ISBLANK('Sensor Specification'!A62),"",'Sensor Specification'!A62) | B55: =IF(ISNUMBER('Sensor Specification'!B62),'Sensor Specification'!B62,"") | C55: =IF(ISNUMBER('Sensor Specification'!C62),'Sensor Specification'!C62+'Sensor Specification'!$B$71,"") | D55: =IF(ISNUMBER('Sensor Specification'!D62),'Sensor Specification'!D62+'Sensor Specification'!$B$72,"") | E55: =IF(ISNUMBER(C55),C55-C54,"") | G55: 2) min. Tolerance Spacing: 1 mm
A58: Date: | C58: Customers Signature:

Sheet Sensor Specification
A2: engionic Fiber Optics GmbH - Ernst-Lau-Straße 8 - 12489 Berlin | H2: V1.14
A4: Production Sheet Number: | E4: Postition: | F4: 1 | G4: of: | H4: 1
A5: Offer Number: | C5: 41260018 | E5: Customer: | F5: NRL
E6: Quantity: | F6: 10
A8: Contact:
A10: Remarks FBGs: | B10: Kein Faserwechsel ohne Absprache; Toleranz erstes bis letztes FBG max 5mm
A12: Remarks Sensor:
A14: Sensor Configuration
A16: Sensor Configuration | B16: Connector Type | C16: =IF(OR(A18=Drawings!A5, A18=Drawings!A6),"Fiber Length (mm)","") -> Fiber Length (mm) | D16: =IF(OR(A18=Drawings!A3, A18=Drawings!A4),"Capillary","") | F16: =IF(OR(A18=Drawings!A4, A18=Drawings!A6),"Tube","")
D17: =IF(OR(A18=Drawings!A3, A18=Drawings!A4),"Diameter (mm)","") | E17: =IF(OR(A18=Drawings!A3, A18=Drawings!A4),"Length (mm)","") | F17: =IF(OR(A18=Drawings!A4, A18=Drawings!A6),"Material","") | G17: =IF(OR(A18=Drawings!A4, A18=Drawings!A6),"Diameter (mm)","") | H17: =IF(OR(A18=Drawings!A4, A18=Drawings!A6),"Length (mm)","")
A18: Fiber Only | B18: FC/APC both ends | C18: 10050
A20: Temperature Sensing Configuration
A21: Working Temperature (°C) | C21: Annealing | D21: Calibration
A22: min | B22: max | D22: from | E22: to
A25: FBG Specification
B26: Wavelength (nm) | C26: Reflectivity (%) | D26: FWHM (nm) | E26: min SLSR (dB) | F26: FBG Length (mm) | G26: FemtoPlus
A27: Nominal Value | B27: - | C27: 0.1 | D27: 0.09 | E27: 8 | F27: 12
A28: Plus Tolerance | B28: 0.1 | C28: 0.04 | D28: 0.02 | E28: - | F28: 2
A29: Minus Tolerance | B29: 0.1 | C29: 0.04 | D29: 0.02 | E29: - | F29: 2
A32: Additional Specifications
B33: Label | C33: Total Fiber Length (mm) | E33: Tolerance FBG Spacing (%)2
B34: on spool | C34: =IF(A18=Drawings!A6,C18,C18+E18+H18) -> 10050 | E34: 2
A36: Wavelength Table
A37: FBG Name | B37: Wavelength (nm) | C37: FBG Position (mm) | D37: FBG Lead Out (mm) | E37: FBG Spacing (mm)
A38: =IF($G$40 > ROW()-ROW($A$38),CONCATENATE("FBG",ROW()-ROW($A$37)),"") -> FBG1 | B38: =G50 -> 1550.39 | C38: =G43 -> 5000 | D38: =IF(ISNUMBER(C38),$C$34-$C38,"") -> 5050 | E38: - | G38: Auto Fill Wavelength Table
A39: =IF($G$40 > ROW()-ROW($A$38),CONCATENATE("FBG",ROW()-ROW($A$37)),"") -> FBG2 | B39: =IF(Definitions!$W$2,IF($G$40 > ROW()-ROW($A$38),$B38+$G$48,""),"") -> 1550.39 | C39: =IF(AND($G$40 > ROW()-ROW($A$38),Definitions!$Y$2),$C38+$G$55,"") -> 5050 | D39: =IF(ISNUMBER(C39),$C$34-$C39,"") -> 5000 | E39: =IF(ISNUMBER(C39),C39-C38,"") -> 50 | G39: Number of FBGs
A40: =IF($G$40 > ROW()-ROW($A$38),CONCATENATE("FBG",ROW()-ROW($A$37)),"") | B40: =IF(Definitions!$W$2,IF($G$40 > ROW()-ROW($A$38),$B39+$G$48,""),"") | C40: =IF(AND($G$40 > ROW()-ROW($A$38),Definitions!$Y$2),$C39+$G$55,"") | D40: =IF(ISNUMBER(C40),$C$34-$C40,"") | E40: =IF(ISNUMBER(C40),C40-C39,"") | G40: 2
A41: =IF($G$40 > ROW()-ROW($A$38),CONCATENATE("FBG",ROW()-ROW($A$37)),"") | B41: =IF(Definitions!$W$2,IF($G$40 > ROW()-ROW($A$38),$B40+$G$48,""),"") | C41: =IF(AND($G$40 > ROW()-ROW($A$38),Definitions!$Y$2),$C40+$G$55,"") | D41: =IF(ISNUMBER(C41),$C$34-$C41,"") | E41: =IF(ISNUMBER(C41),C41-C40,"")
A42: =IF($G$40 > ROW()-ROW($A$38),CONCATENATE("FBG",ROW()-ROW($A$37)),"") | B42: =IF(Definitions!$W$2,IF($G$40 > ROW()-ROW($A$38),$B41+$G$48,""),"") | C42: =IF(AND($G$40 > ROW()-ROW($A$38),Definitions!$Y$2),$C41+$G$55,"") | D42: =IF(ISNUMBER(C42),$C$34-$C42,"") | E42: =IF(ISNUMBER(C42),C42-C41,"") | G42: Position First FBG (mm)
A43: =IF($G$40 > ROW()-ROW($A$38),CONCATENATE("FBG",ROW()-ROW($A$37)),"") | B43: =IF(Definitions!$W$2,IF($G$40 > ROW()-ROW($A$38),$B42+$G$48,""),"") | C43: =IF(AND($G$40 > ROW()-ROW($A$38),Definitions!$Y$2),$C42+$G$55,"") | D43: =IF(ISNUMBER(C43),$C$34-$C43,"") | E43: =IF(ISNUMBER(C43),C43-C42,"") | G43: 5000
A44: =IF($G$40 > ROW()-ROW($A$38),CONCATENATE("FBG",ROW()-ROW($A$37)),"") | B44: =IF(Definitions!$W$2,IF($G$40 > ROW()-ROW($A$38),$B43+$G$48,""),"") | C44: =IF(AND($G$40 > ROW()-ROW($A$38),Definitions!$Y$2),$C43+$G$55,"") | D44: =IF(ISNUMBER(C44),$C$34-$C44,"") | E44: =IF(ISNUMBER(C44),C44-C43,"")
A45: =IF($G$40 > ROW()-ROW($A$38),CONCATENATE("FBG",ROW()-ROW($A$37)),"") | B45: =IF(Definitions!$W$2,IF($G$40 > ROW()-ROW($A$38),$B44+$G$48,""),"") | C45: =IF(AND($G$40 > ROW()-ROW($A$38),Definitions!$Y$2),$C44+$G$55,"") | D45: =IF(ISNUMBER(C45),$C$34-$C45,"") | E45: =IF(ISNUMBER(C45),C45-C44,"") | G45: FBG Wavelength (nm)
A46: =IF($G$40 > ROW()-ROW($A$38),CONCATENATE("FBG",ROW()-ROW($A$37)),"") | B46: =IF(Definitions!$W$2,IF($G$40 > ROW()-ROW($A$38),$B45+$G$48,""),"") | C46: =IF(AND($G$40 > ROW()-ROW($A$38),Definitions!$Y$2),$C45+$G$55,"") | D46: =IF(ISNUMBER(C46),$C$34-$C46,"") | E46: =IF(ISNUMBER(C46),C46-C45,"") | G46: Equal Wavelength Spacing
A47: =IF($G$40 > ROW()-ROW($A$38),CONCATENATE("FBG",ROW()-ROW($A$37)),"") | B47: =IF(Definitions!$W$2,IF($G$40 > ROW()-ROW($A$38),$B46+$G$48,""),"") | C47: =IF(AND($G$40 > ROW()-ROW($A$38),Definitions!$Y$2),$C46+$G$55,"") | D47: =IF(ISNUMBER(C47),$C$34-$C47,"") | E47: =IF(ISNUMBER(C47),C47-C46,"") | G47: Wavelength Spacing (nm)
A48: =IF($G$40 > ROW()-ROW($A$38),CONCATENATE("FBG",ROW()-ROW($A$37)),"") | B48: =IF(Definitions!$W$2,IF($G$40 > ROW()-ROW($A$38),$B47+$G$48,""),"") | C48: =IF(AND($G$40 > ROW()-ROW($A$38),Definitions!$Y$2),$C47+$G$55,"") | D48: =IF(ISNUMBER(C48),$C$34-$C48,"") | E48: =IF(ISNUMBER(C48),C48-C47,"") | G48: 0
A49: =IF($G$40 > ROW()-ROW($A$38),CONCATENATE("FBG",ROW()-ROW($A$37)),"") | B49: =IF(Definitions!$W$2,IF($G$40 > ROW()-ROW($A$38),$B48+$G$48,""),"") | C49: =IF(AND($G$40 > ROW()-ROW($A$38),Definitions!$Y$2),$C48+$G$55,"") | D49: =IF(ISNUMBER(C49),$C$34-$C49,"") | E49: =IF(ISNUMBER(C49),C49-C48,"") | G49: Wavelength first FBG
A50: =IF($G$40 > ROW()-ROW($A$38),CONCATENATE("FBG",ROW()-ROW($A$37)),"") | B50: =IF(Definitions!$W$2,IF($G$40 > ROW()-ROW($A$38),$B49+$G$48,""),"") | C50: =IF(AND($G$40 > ROW()-ROW($A$38),Definitions!$Y$2),$C49+$G$55,"") | D50: =IF(ISNUMBER(C50),$C$34-$C50,"") | E50: =IF(ISNUMBER(C50),C50-C49,"") | G50: 1550.39
A51: =IF($G$40 > ROW()-ROW($A$38),CONCATENATE("FBG",ROW()-ROW($A$37)),"") | B51: =IF(Definitions!$W$2,IF($G$40 > ROW()-ROW($A$38),$B50+$G$48,""),"") | C51: =IF(AND($G$40 > ROW()-ROW($A$38),Definitions!$Y$2),$C50+$G$55,"") | D51: =IF(ISNUMBER(C51),$C$34-$C51,"") | E51: =IF(ISNUMBER(C51),C51-C50,"")
A52: =IF($G$40 > ROW()-ROW($A$38),CONCATENATE("FBG",ROW()-ROW($A$37)),"") | B52: =IF(Definitions!$W$2,IF($G$40 > ROW()-ROW($A$38),$B51+$G$48,""),"") | C52: =IF(AND($G$40 > ROW()-ROW($A$38),Definitions!$Y$2),$C51+$G$55,"") | D52: =IF(ISNUMBER(C52),$C$34-$C52,"") | E52: =IF(ISNUMBER(C52),C52-C51,"") | G52: FBG Spacing (mm)
A53: =IF($G$40 > ROW()-ROW($A$38),CONCATENATE("FBG",ROW()-ROW($A$37)),"") | B53: =IF(Definitions!$W$2,IF($G$40 > ROW()-ROW($A$38),$B52+$G$48,""),"") | C53: =IF(AND($G$40 > ROW()-ROW($A$38),Definitions!$Y$2),$C52+$G$55,"") | D53: =IF(ISNUMBER(C53),$C$34-$C53,"") | E53: =IF(ISNUMBER(C53),C53-C52,"") | G53: Equal FBG Spacing
...

Sheet Definitions
A1: Contact | C1: Fiber Type | D1: Core Type | E1: Mode Field | F1: Fiber Cladding | G1: Coating | H1: Manufacturer | I1: ITU-T | K1: Provided | M1: FemtoPlus | O1: Apodized | Q1: Spectrum | S1: FBG | U1: Fiber | W1: WL spacing | Y1: Pos spacing | AA1: Connector Type | AC1: Tubings | AD1: =IF($AC$12=Definitions!AC2,"AF",IF($AC$12=Definitions!AC3,"AG",IF($AC$12=Definitions!AC4,"AH",IF($AC$12=Definitions!AC5,"AI",IF($AC$12=Definitions!AC6,"AJ",IF($AC$12=Definitions!AC7,"AK",IF($AC$12=Definitions!AC8,"AJ"))))))) -> AJ | AF1: PVC | AG1: PTFE | AH1: Hytrel | AI1: PS | AJ1: Flex Steel Tubing | AK1: PEEK | AL1: StainlessSteel | AN1: Cappil. Diam | AP1: Label | AR1: simplified packaging
A2: Friedrich | C2: SMF-28 Ultra | D2: Single Mode | E2: 10.4 | F2: 125 | G2: Acrylate | H2: Corning | I2: G.657.A1 | K2: eFG | M2: yes | O2: yes | Q2: linear | S2: black, FBG-length (±1mm tolerance) | U2: black, 3 cm dots | W2: TRUE | Y2: TRUE | AA2: FC/APC | AC2: PVC | AD2: {=INDIRECT($AD$1&2)} -> 3 | AF2: 1.7 | AG2: 1 | AH2: 0.9 | AI2: 2 | AJ2: 3 | AK2: 0.9 | AL2: 4 | AN2: 0.8 | AP2: on spool | AR2: yes
A3: Gillooly | C3: SMF-28 Ultra 200 | D3: Single Mode | E3: 10.4 | F3: 125 | G3: Acrylate | H3: Corning | I3: G.657.A1 | K3: customer | M3: no | O3: no | Q3: logarithmic | S3: no | U3: black | AA3: FC/AP | AC3: PTFE | AD3: {=IF(ISNUMBER(INDIRECT($AD$1&3)),INDIRECT($AD$1&3),"")} -> 4 | AF3: 2 | AG3: 3 | AJ3: 4 | AL3: 6.2 | AN3: 1 | AP3: on fiber | AR3: no
A4: Gong | C4: SM1330-E9/125PI | D4: Single Mode | E4: 10,4 | F4: 125 | G4: Polyimide | H4: J-Fiber | I4: - | S4: black, plus black 25 mm to sides | U4: green | AA4: LC/APC | AC4: Hytrel | AD4: {=IF(ISNUMBER(INDIRECT($AD$1&4)),INDIRECT($AD$1&4),"")} -> 6.2 | AF4: 3 | AG4: 4 | AJ4: 6.2 | AN4: 1.2
A5: Kampling | C5: SM1500SC(7/80)P | D5: Pure Core | E5: 6,7 - 7,6 | F5: 80 | G5: Polyimide | H5: Fibercore | I5: - | S5: Other (see Remarks) | U5: no | AA5: E2000/APC (ext.) | AC5: PS | AD5: {=IF(ISNUMBER(INDIRECT($AD$1&5)),INDIRECT($AD$1&5),"")} | AN5: 1.5
A6: Reif | C6: SM1250BI(9.8/125)P | D6: Bend Insensitive | E6: 9 - 10,6 | F6: 125 | G6: Polyimide | H6: Fibercore | I6: - | U6: Other (see Remarks) | AA6: DIN | AC6: Flex Steel Tubing | AD6: {=IF(ISNUMBER(INDIRECT($AD$1&6)),INDIRECT($AD$1&6),"")} | AN6: 1.8
A7: Vasileiou | C7: SM1250SC(9/125) | D7: Pure Core | E7: 8,3 - 9,6 | F7: 125 | G7: Acrylate | H7: Fibercore | I7: - | AA7: FC/APC both ends | AC7: PEEK | AD7: {=IF(ISNUMBER(INDIRECT($AD$1&7)),INDIRECT($AD$1&7),"")} | AN7: 2
A8: Vouilleme | C8: SM1250SC(9/125)P | D8: Pure Core | E8: 8,3 - 9,6 | F8: 125 | G8: Polyimide | H8: Fibercore | I8: - | AA8: LC/APC both ends | AD8: {=IF(ISNUMBER(INDIRECT($AD$1&8)),INDIRECT($AD$1&8),"")} | AN8: 3
A9: Yang | C9: SM1250SC(10/125)P | D9: Pure Core | E9: 9,2 - 10,8 | F9: 125 | G9: Polyimide | H9: Fibercore | I9: -
A10: Hoffmann | C10: IXF-RAD-SM-1550-014-PI | D10: Radiation Hard | E10: 8 - 10 | F10: 125 | G10: Polyimide | H10: iXblue | I10: -
C11: SMF-60-MTDA-125-1 | D11: Pure Core | E11: 9,3 - 10,7 | F11: 125 | G11: Acrylate | H11: Verrillon | I11: -
C12: Ormocer | D12: Single Mode | E12: - | F12: 125 | G12: Ormocer | H12: J-Fiber | I12: - | AC12: ='Sensor Specification'!F18 -> 0
C13: Single Mode Acrylate | D13: Single Mode | E13: - | F13: - | G13: Acrylate | H13: - | I13: -
C14: Single Mode PI | D14: Single Mode | E14: - | F14: - | G14: Polyimide | H14: - | I14: -
C15: Pure Core PI | D15: Pure Core | E15: - | F15: - | G15: Polyimide | H15: - | I15: -
C16: Other (see Remarks) | D16: - | E16: - | F16: - | G16: - | H16: - | I16: -

Sheet Drawings
B1: =IF('Sensor Specification'!A18=Drawings!A3,3,IF('Sensor Specification'!A18=Drawings!A4,4,IF('Sensor Specification'!A18=Drawings!A5,5,IF('Sensor Specification'!A18=Drawings!A6,6,7)))) -> 5
A3: Capillary without Tube
A4: Capillary with Tube
A5: Fiber Only
A6: Fiber with Tube
